<?xml version="1.0" encoding="utf-8"?>
<!-- This URDF was automatically created by SolidWorks to URDF Exporter! Originally created by Stephen Brawner (brawner@gmail.com) 
     Commit Version: 1.6.0-4-g7f85cfe  Build Version: 1.6.7995.38578
     For more information, please see http://wiki.ros.org/sw_urdf_exporter -->
<robot
  name="6dof_robot">
  <link
    name="base_link">
    <inertial>
      <origin
        xyz="-1.296E-18 1.8651E-34 0.018756"
        rpy="0 0 0" />
      <mass
        value="0.25871" />
      <inertia
        ixx="0.00016856"
        ixy="-6.1834E-37"
        ixz="-2.5521E-21"
        iyy="0.00016856"
        iyz="3.9096E-37"
        izz="0.00026732" />
    </inertial>
    <visual>
      <origin
        xyz="0 0 0"
        rpy="0 0 0" />
      <geometry>
        <mesh
          filename="package://6dof_robot/meshes/base_link.STL" />
      </geometry>
      <material
        name="">
        <color
          rgba="1 1 1 1" />
      </material>
    </visual>
    <collision>
      <origin
        xyz="0 0 0"
        rpy="0 0 0" />
      <geometry>
        <mesh
          filename="package://6dof_robot/meshes/base_link.STL" />
      </geometry>
    </collision>
  </link>
  <link
    name="link_0">
    <inertial>
      <origin
        xyz="-0.0047986 -2.0591E-07 0.07937"
        rpy="0 0 0" />
      <mass
        value="0.62849" />
      <inertia
        ixx="0.0018753"
        ixy="-1.8676E-11"
        ixz="1.8991E-06"
        iyy="0.0018426"
        iyz="4.9506E-12"
        izz="0.00049418" />
    </inertial>
    <visual>
      <origin
        xyz="0 0 0"
        rpy="0 0 0" />
      <geometry>
        <mesh
          filename="package://6dof_robot/meshes/link_0.STL" />
      </geometry>
      <material
        name="">
        <color
          rgba="1 0 0 1" />
      </material>
    </visual>
    <collision>
      <origin
        xyz="0 0 0"
        rpy="0 0 0" />
      <geometry>
        <mesh
          filename="package://6dof_robot/meshes/link_0.STL" />
      </geometry>
    </collision>
  </link>
  <joint
    name="joint_1"
    type="revolute">
    <origin
      xyz="0 0 0.0405"
      rpy="0 0 0" />
    <parent
      link="base_link" />
    <child
      link="link_0" />
    <axis
      xyz="0 0 1" />
    <limit
      lower="-6.2832"
      upper="6.2832"
      effort="0"
      velocity="3.1416" />
  </joint>
  <link
    name="link_1">
    <inertial>
      <origin
        xyz="0.1072 -4.8392E-07 0.064858"
        rpy="0 0 0" />
      <mass
        value="1.6017" />
      <inertia
        ixx="0.016333"
        ixy="1.0726E-08"
        ixz="-0.0013297"
        iyy="0.019385"
        iyz="1.2251E-07"
        izz="0.0040931" />
    </inertial>
    <visual>
      <origin
        xyz="0 0 0"
        rpy="0 0 0" />
      <geometry>
        <mesh
          filename="package://6dof_robot/meshes/link_1.STL" />
      </geometry>
      <material
        name="">
        <color
          rgba="1 0.5 0 1" />
      </material>
    </visual>
    <collision>
      <origin
        xyz="0 0 0"
        rpy="0 0 0" />
      <geometry>
        <mesh
          filename="package://6dof_robot/meshes/link_1.STL" />
      </geometry>
    </collision>
  </link>
  <joint
    name="joint_2"
    type="revolute">
    <origin
      xyz="0 0 0.08"
      rpy="0 0 0" />
    <parent
      link="link_0" />
    <child
      link="link_1" />
    <axis
      xyz="1 0 0" />
    <limit
      lower="-3.1416"
      upper="3.1416"
      effort="0"
      velocity="3.1416" />
  </joint>
  <link
    name="link_2">
    <inertial>
      <origin
        xyz="-0.05911 9.0122E-19 0.074306"
        rpy="0 0 0" />
      <mass
        value="0.83881" />
      <inertia
        ixx="0.0073165"
        ixy="5.9473E-20"
        ixz="0.0026694"
        iyy="0.0096228"
        iyz="-3.396E-20"
        izz="0.002593" />
    </inertial>
    <visual>
      <origin
        xyz="0 0 0"
        rpy="0 0 0" />
      <geometry>
        <mesh
          filename="package://6dof_robot/meshes/link_2.STL" />
      </geometry>
      <material
        name="">
        <color
          rgba="1 1 0 1" />
      </material>
    </visual>
    <collision>
      <origin
        xyz="0 0 0"
        rpy="0 0 0" />
      <geometry>
        <mesh
          filename="package://6dof_robot/meshes/link_2.STL" />
      </geometry>
    </collision>
  </link>
  <joint
    name="joint_3"
    type="revolute">
    <origin
      xyz="0.12 0 0.29"
      rpy="0 0 0" />
    <parent
      link="link_1" />
    <child
      link="link_2" />
    <axis
      xyz="1 0 0" />
    <limit
      lower="-3.1416"
      upper="3.1416"
      effort="0"
      velocity="3.1416" />
  </joint>
  <link
    name="link_3">
    <inertial>
      <origin
        xyz="0.017716 5.7646E-09 0.0018258"
        rpy="0 0 0" />
      <mass
        value="0.25205" />
      <inertia
        ixx="7.8585E-05"
        ixy="4.51E-12"
        ixz="8.1528E-06"
        iyy="0.00056767"
        iyz="1.261E-11"
        izz="0.00057024" />
    </inertial>
    <visual>
      <origin
        xyz="0 0 0"
        rpy="0 0 0" />
      <geometry>
        <mesh
          filename="package://6dof_robot/meshes/link_3.STL" />
      </geometry>
      <material
        name="">
        <color
          rgba="0 0.65 0 1" />
      </material>
    </visual>
    <collision>
      <origin
        xyz="0 0 0"
        rpy="0 0 0" />
      <geometry>
        <mesh
          filename="package://6dof_robot/meshes/link_3.STL" />
      </geometry>
    </collision>
  </link>
  <joint
    name="joint_4"
    type="revolute">
    <origin
      xyz="-0.102 0 0.276"
      rpy="0 0 0" />
    <parent
      link="link_2" />
    <child
      link="link_3" />
    <axis
      xyz="0 0 1" />
    <limit
      lower="-3.1416"
      upper="3.1416"
      effort="0"
      velocity="5.236" />
  </joint>
  <link
    name="link_4">
    <inertial>
      <origin
        xyz="0.0018257 -8.8581E-08 0.017716"
        rpy="0 0 0" />
      <mass
        value="0.25205" />
      <inertia
        ixx="0.00057024"
        ixy="-7.7669E-10"
        ixz="8.1528E-06"
        iyy="0.00056766"
        iyz="-3.0278E-10"
        izz="7.8585E-05" />
    </inertial>
    <visual>
      <origin
        xyz="0 0 0"
        rpy="0 0 0" />
      <geometry>
        <mesh
          filename="package://6dof_robot/meshes/link_4.STL" />
      </geometry>
      <material
        name="">
        <color
          rgba="0 0 1 1" />
      </material>
    </visual>
    <collision>
      <origin
        xyz="0 0 0"
        rpy="0 0 0" />
      <geometry>
        <mesh
          filename="package://6dof_robot/meshes/link_4.STL" />
      </geometry>
    </collision>
  </link>
  <joint
    name="joint_5"
    type="revolute">
    <origin
      xyz="0.09 0 0"
      rpy="0 0 0" />
    <parent
      link="link_3" />
    <child
      link="link_4" />
    <axis
      xyz="1 0 0" />
    <limit
      lower="-3.1416"
      upper="3.1416"
      effort="0"
      velocity="5.236" />
  </joint>
  <link
    name="link_5">
    <inertial>
      <origin
        xyz="0.022589 -1.0021E-06 0.0016987"
        rpy="0 0 0" />
      <mass
        value="0.27088" />
      <inertia
        ixx="9.3405E-05"
        ixy="1.7584E-08"
        ixz="1.0399E-05"
        iyy="0.00066141"
        iyz="-3.002E-09"
        izz="0.00066393" />
    </inertial>
    <visual>
      <origin
        xyz="0 0 0"
        rpy="0 0 0" />
      <geometry>
        <mesh
          filename="package://6dof_robot/meshes/link_5.STL" />
      </geometry>
      <material
        name="">
        <color
          rgba="0.5 0 1 1" />
      </material>
    </visual>
    <collision>
      <origin
        xyz="0 0 0"
        rpy="0 0 0" />
      <geometry>
        <mesh
          filename="package://6dof_robot/meshes/link_5.STL" />
      </geometry>
    </collision>
  </link>
  <joint
    name="joint_6"
    type="revolute">
    <origin
      xyz="0 0 0.09"
      rpy="0 0 0" />
    <parent
      link="link_4" />
    <child
      link="link_5" />
    <axis
      xyz="0 0 -1" />
    <limit
      lower="-6.283188"
      upper="6.283188"
      effort="0"
      velocity="5.23599" />
  </joint>
</robot>